Workbook
Name SegmentaçãodeDados_Origem: #N/A
Name SegmentaçãodeDados_País_de_Destino: #N/A

Sheet Comece Aqui
A2: • | B2: Nesse arquivo você encontra 30 exercícios baseados em situações do dia a dia de trabalho e em questões de processos seletivos. Esses exercícios abragem os seguintes módulos do Excel Impressionador:
B4: Conceitos Introdutórios
B5: Atalhos
B6: Formatação
B7: Funções Básicas
B8: Classificar e Filtrar
B9: Ferramentas de Dados
B10: Funções Mercado de Trabalho.
A12: • | B12: Sugiro fortemente que assista todas as aulas dos módulos acima antes de responder as questões a seguir.
A14: • | B14: Você deve responder as questões nas planilhas azuis utilizando as demais planilhas como base de dados. Utilize quaisquer ferramentas aprendidas nos módulos citados anteriormente para responder as questões.
B15: Algumas perguntas podem ser respondidas de mais de uma forma, utilizando fórmulas e ferramentas diferentes do Excel. Sempre que se deparar com uma questão como essa, sugiro que responda a mesma questão de todas as formas que conseguir. Pode parecer estranho responder a mesma questão 2 ou 3 vezes, mas vai ser uma excelente prática para você resolver um problema ou desafio no Excel de diversas maneiras possíveis.
A18: • | B18: Preste atenção nos enunciados. Entendender as questões já faz parte do exercício, da mesma forma que entender as questões em um processo seletivo e as demandas do seu chefe é uma forma de avaliar seu trabalho e conhecimento de Excel.
A20: • | B20: O objetivo desses exercícios é apenas desenvolver seu conhecimento e prática com as ferramentas e fórmulas do Excel aprendidas até agora. Você não receberá uma nota (como se fosse uma prova de colégio) e tampouco o certificado do curso depende dessas questões.
A23: • | B23: Após responder todas as questões, assista as demais aulas desse módulo para acompanhar a correção de cada pergunta.

Sheet Base de Dados
A1: Descrição | B1: Código | C1: Origem | D1: Região | E1: Chave do Produto | F1: Data de Validade | G1: Urgência de Envio de Produtos | H1: Ano | I1: Mês | J1: Custo de Produção | K1: País de Destino | N1: {=_xlfn.UNIQUE(B:B)} -> Código | O1: Repetições | R1: Validação de Dados | U1: Validação de dados
A2: Pacofapipe | B2: H574P162 | C2: ES | D2: =VLOOKUP(Tabela1[[#This Row],[Origem]], 'Perguntas 1 a 24'!$J$28:$K$34, 2, 0) -> Sudeste | E2: =Tabela1[[#This Row],[Descrição]]&"-"&Tabela1[[#This Row],[Código]]&"/"&Tabela1[[#This Row],[Origem]] -> Pacofapipe-H574P162/ES | F2: 45425 | G2: {=_xlfn.IFS(AND(Tabela1[[#This Row],[Data de Validade]]<= DATE(2025, 12, 31), Tabela1[[#This Row],[Custo de Produção]]>50000), "Urgente e Caro", AND(Tabela1[[#This Row],[Data de Validade]]<= DATE(2025, 12, 31), Tabela1[[#This Row],[Custo de Produção]]<= 50000), "Urgente", AND(F2>= DATE(2026,1,1), F2<= DATE(2028, 12, 31), J2>50000), "Pendente e Caro", AND(F2>= DATE(2026,1,1), F2<= DATE(2028, 12, 31), J2<=50000), "Pendente", F2>= DATE(2029,1,1), "Não prioeitário")} -> Urgente e Caro | H2: =YEAR(Tabela1[[#This Row],[Data de Validade]]) -> 2024 | I2: =MONTH(Tabela1[[#This Row],[Data de Validade]]) -> 5 | J2: 111076 | K2: Holanda | N2: H574P162 | O2: =COUNTIFS(B:B,N2) -> 1 | R2: País | S2: Holanda | U2: Somatório | V2: Média | W2: Contagem | X2: Máximo | Y2: Mínimo
A3: Nolifepa | B3: H735H276 | C3: SP | D3: =VLOOKUP(Tabela1[[#This Row],[Origem]], 'Perguntas 1 a 24'!$J$28:$K$34, 2, 0) -> Sudeste | E3: =Tabela1[[#This Row],[Descrição]]&"-"&Tabela1[[#This Row],[Código]]&"/"&Tabela1[[#This Row],[Origem]] -> Nolifepa-H735H276/SP | F3: 45425 | G3: {=_xlfn.IFS(AND(Tabela1[[#This Row],[Data de Validade]]<= DATE(2025, 12, 31), Tabela1[[#This Row],[Custo de Produção]]>50000), "Urgente e Caro", AND(Tabela1[[#This Row],[Data de Validade]]<= DATE(2025, 12, 31), Tabela1[[#This Row],[Custo de Produção]]<= 50000), "Urgente", AND(F3>= DATE(2026,1,1), F3<= DATE(2028, 12, 31), J3>50000), "Pendente e Caro", AND(F3>= DATE(2026,1,1), F3<= DATE(2028, 12, 31), J3<=50000), "Pendente", F3>= DATE(2029,1,1), "Não prioeitário")} -> Urgente e Caro | H3: =YEAR(Tabela1[[#This Row],[Data de Validade]]) -> 2024 | I3: =MONTH(Tabela1[[#This Row],[Data de Validade]]) -> 5 | J3: 107568 | K3: Holanda | N3: H735H276 | O3: =COUNTIFS(B:B,N3) -> 1 | R3: Ano | S3: 2028 | U3: =SUMIFS(J:J, K:K, S2, H:H, S3) -> 9841767 | V3: =AVERAGEIFS(J:J, K:K, S2) -> 69997.152 | W3: =COUNTIFS(K:K, S2) -> 958 | X3: =_xlfn.MAXIFS(J:J, K:K, S2) -> 119595 | Y3: =_xlfn.MINIFS(J:J, K:K, S2) -> 20081
A4: Rapopa | B4: H538H378 | C4: MG | D4: =VLOOKUP(Tabela1[[#This Row],[Origem]], 'Perguntas 1 a 24'!$J$28:$K$34, 2, 0) -> Sudeste | E4: =Tabela1[[#This Row],[Descrição]]&"-"&Tabela1[[#This Row],[Código]]&"/"&Tabela1[[#This Row],[Origem]] -> Rapopa-H538H378/MG | F4: 45425 | G4: {=_xlfn.IFS(AND(Tabela1[[#This Row],[Data de Validade]]<= DATE(2025, 12, 31), Tabela1[[#This Row],[Custo de Produção]]>50000), "Urgente e Caro", AND(Tabela1[[#This Row],[Data de Validade]]<= DATE(2025, 12, 31), Tabela1[[#This Row],[Custo de Produção]]<= 50000), "Urgente", AND(F4>= DATE(2026,1,1), F4<= DATE(2028, 12, 31), J4>50000), "Pendente e Caro", AND(F4>= DATE(2026,1,1), F4<= DATE(2028, 12, 31), J4<=50000), "Pendente", F4>= DATE(2029,1,1), "Não prioeitário")} -> Urgente e Caro | H4: =YEAR(Tabela1[[#This Row],[Data de Validade]]) -> 2024 | I4: =MONTH(Tabela1[[#This Row],[Data de Validade]]) -> 5 | J4: 86399 | K4: Austrália | N4: H538H378 | O4: =COUNTIFS(B:B,N4) -> 1 | R4: Custo de Produção | S4: =SUMIFS(J:J,K:K,S2, H:H, S3) -> 9841767
A5: Godopadu | B5: P116P159 | C5: SP | D5: =VLOOKUP(Tabela1[[#This Row],[Origem]], 'Perguntas 1 a 24'!$J$28:$K$34, 2, 0) -> Sudeste | E5: =Tabela1[[#This Row],[Descrição]]&"-"&Tabela1[[#This Row],[Código]]&"/"&Tabela1[[#This Row],[Origem]] -> Godopadu-P116P159/SP | F5: 45425 | G5: {=_xlfn.IFS(AND(Tabela1[[#This Row],[Data de Validade]]<= DATE(2025, 12, 31), Tabela1[[#This Row],[Custo de Produção]]>50000), "Urgente e Caro", AND(Tabela1[[#This Row],[Data de Validade]]<= DATE(2025, 12, 31), Tabela1[[#This Row],[Custo de Produção]]<= 50000), "Urgente", AND(F5>= DATE(2026,1,1), F5<= DATE(2028, 12, 31), J5>50000), "Pendente e Caro", AND(F5>= DATE(2026,1,1), F5<= DATE(2028, 12, 31), J5<=50000), "Pendente", F5>= DATE(2029,1,1), "Não prioeitário")} -> Urgente e Caro | H5: =YEAR(Tabela1[[#This Row],[Data de Validade]]) -> 2024 | I5: =MONTH(Tabela1[[#This Row],[Data de Validade]]) -> 5 | J5: 80288 | K5: Panamá | N5: P116P159 | O5: =COUNTIFS(B:B,N5) -> 1 | R5: Análise dos dados - Geral
A6: Raliru | B6: H515P175 | C6: ES | D6: =VLOOKUP(Tabela1[[#This Row],[Origem]], 'Perguntas 1 a 24'!$J$28:$K$34, 2, 0) -> Sudeste | E6: =Tabela1[[#This Row],[Descrição]]&"-"&Tabela1[[#This Row],[Código]]&"/"&Tabela1[[#This Row],[Origem]] -> Raliru-H515P175/ES | F6: 45425 | G6: {=_xlfn.IFS(AND(Tabela1[[#This Row],[Data de Validade]]<= DATE(2025, 12, 31), Tabela1[[#This Row],[Custo de Produção]]>50000), "Urgente e Caro", AND(Tabela1[[#This Row],[Data de Validade]]<= DATE(2025, 12, 31), Tabela1[[#This Row],[Custo de Produção]]<= 50000), "Urgente", AND(F6>= DATE(2026,1,1), F6<= DATE(2028, 12, 31), J6>50000), "Pendente e Caro", AND(F6>= DATE(2026,1,1), F6<= DATE(2028, 12, 31), J6<=50000), "Pendente", F6>= DATE(2029,1,1), "Não prioeitário")} -> Urgente e Caro | H6: =YEAR(Tabela1[[#This Row],[Data de Validade]]) -> 2024 | I6: =MONTH(Tabela1[[#This Row],[Data de Validade]]) -> 5 | J6: 80281 | K6: Panamá | N6: H515P175 | O6: =COUNTIFS(B:B,N6) -> 1 | R6: Somatório do Custo | S6: Média de Custo | T6: Contagem de Transações | U6: Valor Máximo de Custo | V6: Valor Mínimo de Custo
A7: Ratena | B7: H917H959 | C7: SP | D7: =VLOOKUP(Tabela1[[#This Row],[Origem]], 'Perguntas 1 a 24'!$J$28:$K$34, 2, 0) -> Sudeste | E7: =Tabela1[[#This Row],[Descrição]]&"-"&Tabela1[[#This Row],[Código]]&"/"&Tabela1[[#This Row],[Origem]] -> Ratena-H917H959/SP | F7: 45425 | G7: {=_xlfn.IFS(AND(Tabela1[[#This Row],[Data de Validade]]<= DATE(2025, 12, 31), Tabela1[[#This Row],[Custo de Produção]]>50000), "Urgente e Caro", AND(Tabela1[[#This Row],[Data de Validade]]<= DATE(2025, 12, 31), Tabela1[[#This Row],[Custo de Produção]]<= 50000), "Urgente", AND(F7>= DATE(2026,1,1), F7<= DATE(2028, 12, 31), J7>50000), "Pendente e Caro", AND(F7>= DATE(2026,1,1), F7<= DATE(2028, 12, 31), J7<=50000), "Pendente", F7>= DATE(2029,1,1), "Não prioeitário")} -> Urgente e Caro | H7: =YEAR(Tabela1[[#This Row],[Data de Validade]]) -> 2024 | I7: =MONTH(Tabela1[[#This Row],[Data de Validade]]) -> 5 | J7: 75598 | K7: Panamá | N7: H917H959 | O7: =COUNTIFS(B:B,N7) -> 1 | R7: =SUM(J:J) -> 272140218 | S7: =AVERAGE(J:J) -> 70594.09 | T7: =COUNT(J:J) -> 3855 | U7: =MAX(Tabela1[Custo de Produção]) -> 119945 | V7: =MIN(Tabela1[Custo de Produção]) -> 20044
A8: Roduma | B8: P363P987 | C8: GO | D8: =VLOOKUP(Tabela1[[#This Row],[Origem]], 'Perguntas 1 a 24'!$J$28:$K$34, 2, 0) -> Centro-Oeste | E8: =Tabela1[[#This Row],[Descrição]]&"-"&Tabela1[[#This Row],[Código]]&"/"&Tabela1[[#This Row],[Origem]] -> Roduma-P363P987/GO | F8: 45425 | G8: {=_xlfn.IFS(AND(Tabela1[[#This Row],[Data de Validade]]<= DATE(2025, 12, 31), Tabela1[[#This Row],[Custo de Produção]]>50000), "Urgente e Caro", AND(Tabela1[[#This Row],[Data de Validade]]<= DATE(2025, 12, 31), Tabela1[[#This Row],[Custo de Produção]]<= 50000), "Urgente", AND(F8>= DATE(2026,1,1), F8<= DATE(2028, 12, 31), J8>50000), "Pendente e Caro", AND(F8>= DATE(2026,1,1), F8<= DATE(2028, 12, 31), J8<=50000), "Pendente", F8>= DATE(2029,1,1), "Não prioeitário")} -> Urgente e Caro | H8: =YEAR(Tabela1[[#This Row],[Data de Validade]]) -> 2024 | I8: =MONTH(Tabela1[[#This Row],[Data de Validade]]) -> 5 | J8: 65781 | K8: Austrália | N8: P363P987 | O8: =COUNTIFS(B:B,N8) -> 1 | Y8: Contagem
A9: Firamu | B9: P589P568 | C9: ES | D9: =VLOOKUP(Tabela1[[#This Row],[Origem]], 'Perguntas 1 a 24'!$J$28:$K$34, 2, 0) -> Sudeste | E9: =Tabela1[[#This Row],[Descrição]]&"-"&Tabela1[[#This Row],[Código]]&"/"&Tabela1[[#This Row],[Origem]] -> Firamu-P589P568/ES | F9: 45425 | G9: {=_xlfn.IFS(AND(Tabela1[[#This Row],[Data de Validade]]<= DATE(2025, 12, 31), Tabela1[[#This Row],[Custo de Produção]]>50000), "Urgente e Caro", AND(Tabela1[[#This Row],[Data de Validade]]<= DATE(2025, 12, 31), Tabela1[[#This Row],[Custo de Produção]]<= 50000), "Urgente", AND(F9>= DATE(2026,1,1), F9<= DATE(2028, 12, 31), J9>50000), "Pendente e Caro", AND(F9>= DATE(2026,1,1), F9<= DATE(2028, 12, 31), J9<=50000), "Pendente", F9>= DATE(2029,1,1), "Não prioeitário")} -> Urgente e Caro | H9: =YEAR(Tabela1[[#This Row],[Data de Validade]]) -> 2024 | I9: =MONTH(Tabela1[[#This Row],[Data de Validade]]) -> 5 | J9: 57874 | K9: Espanha | N9: P589P568 | O9: =COUNTIFS(B:B,N9) -> 1 | S9: Resumo Custo de Produção por Região | Y9: Austrália | Z9: Espanha | AA9: Holanda | AB9: Panamá
A10: Namirolacu | B10: P445P823 | C10: ES | D10: =VLOOKUP(Tabela1[[#This Row],[Origem]], 'Perguntas 1 a 24'!$J$28:$K$34, 2, 0) -> Sudeste | E10: =Tabela1[[#This Row],[Descrição]]&"-"&Tabela1[[#This Row],[Código]]&"/"&Tabela1[[#This Row],[Origem]] -> Namirolacu-P445P823/ES | F10: 45425 | G10: {=_xlfn.IFS(AND(Tabela1[[#This Row],[Data de Validade]]<= DATE(2025, 12, 31), Tabela1[[#This Row],[Custo de Produção]]>50000), "Urgente e Caro", AND(Tabela1[[#This Row],[Data de Validade]]<= DATE(2025, 12, 31), Tabela1[[#This Row],[Custo de Produção]]<= 50000), "Urgente", AND(F10>= DATE(2026,1,1), F10<= DATE(2028, 12, 31), J10>50000), "Pendente e Caro", AND(F10>= DATE(2026,1,1), F10<= DATE(2028, 12, 31), J10<=50000), "Pendente", F10>= DATE(2029,1,1), "Não prioeitário")} -> Urgente e Caro | H10: =YEAR(Tabela1[[#This Row],[Data de Validade]]) -> 2024 | I10: =MONTH(Tabela1[[#This Row],[Data de Validade]]) -> 5 | J10: 56196 | K10: Austrália | N10: P445P823 | O10: =COUNTIFS(B:B,N10) -> 1 | S10: Austrália | T10: Espanha | U10: Holanda | V10: Panamá | X10: Nordeste | Y10: =COUNTIFS($K:$K, Y$9, $D:$D, $X10) -> 307 | Z10: =COUNTIFS($K:$K, Z$9, $D:$D, $X10) -> 257 | AA10: =COUNTIFS($K:$K, AA$9, $D:$D, $X10) -> 290 | AB10: =COUNTIFS($K:$K, AB$9, $D:$D, $X10) -> 274
A11: Turucego | B11: H647P923 | C11: GO | D11: =VLOOKUP(Tabela1[[#This Row],[Origem]], 'Perguntas 1 a 24'!$J$28:$K$34, 2, 0) -> Centro-Oeste | E11: =Tabela1[[#This Row],[Descrição]]&"-"&Tabela1[[#This Row],[Código]]&"/"&Tabela1[[#This Row],[Origem]] -> Turucego-H647P923/GO | F11: 45426 | G11: {=_xlfn.IFS(AND(Tabela1[[#This Row],[Data de Validade]]<= DATE(2025, 12, 31), Tabela1[[#This Row],[Custo de Produção]]>50000), "Urgente e Caro", AND(Tabela1[[#This Row],[Data de Validade]]<= DATE(2025, 12, 31), Tabela1[[#This Row],[Custo de Produção]]<= 50000), "Urgente", AND(F11>= DATE(2026,1,1), F11<= DATE(2028, 12, 31), J11>50000), "Pendente e Caro", AND(F11>= DATE(2026,1,1), F11<= DATE(2028, 12, 31), J11<=50000), "Pendente", F11>= DATE(2029,1,1), "Não prioeitário")} -> Urgente e Caro | H11: =YEAR(Tabela1[[#This Row],[Data de Validade]]) -> 2024 | I11: =MONTH(Tabela1[[#This Row],[Data de Validade]]) -> 5 | J11: 56196 | K11: Panamá | N11: H647P923 | O11: =COUNTIFS(B:B,N11) -> 1 | R11: Nordeste | S11: =SUMIFS($J:$J,$K:$K, S$10, $D:$D, $R11) -> 21582443 | T11: =SUMIFS($J:$J,$K:$K, T$10, $D:$D, $R11) -> 18432363 | U11: =SUMIFS($J:$J,$K:$K, U$10, $D:$D, $R11) -> 19384102 | V11: =SUMIFS($J:$J,$K:$K, V$10, $D:$D, $R11) -> 19329788 | X11: Sudeste | Y11: =COUNTIFS($K:$K, Y$9, $D:$D, $X11) -> 528 | Z11: =COUNTIFS($K:$K, Z$9, $D:$D, $X11) -> 540 | AA11: =COUNTIFS($K:$K, AA$9, $D:$D, $X11) -> 532 | AB11: =COUNTIFS($K:$K, AB$9, $D:$D, $X11) -> 545
A12: Tugafacumi | B12: P915P867 | C12: RJ | D12: =VLOOKUP(Tabela1[[#This Row],[Origem]], 'Perguntas 1 a 24'!$J$28:$K$34, 2, 0) -> Sudeste | E12: =Tabela1[[#This Row],[Descrição]]&"-"&Tabela1[[#This Row],[Código]]&"/"&Tabela1[[#This Row],[Origem]] -> Tugafacumi-P915P867/RJ | F12: 45426 | G12: {=_xlfn.IFS(AND(Tabela1[[#This Row],[Data de Validade]]<= DATE(2025, 12, 31), Tabela1[[#This Row],[Custo de Produção]]>50000), "Urgente e Caro", AND(Tabela1[[#This Row],[Data de Validade]]<= DATE(2025, 12, 31), Tabela1[[#This Row],[Custo de Produção]]<= 50000), "Urgente", AND(F12>= DATE(2026,1,1), F12<= DATE(2028, 12, 31), J12>50000), "Pendente e Caro", AND(F12>= DATE(2026,1,1), F12<= DATE(2028, 12, 31), J12<=50000), "Pendente", F12>= DATE(2029,1,1), "Não prioeitário")} -> Urgente e Caro | H12: =YEAR(Tabela1[[#This Row],[Data de Validade]]) -> 2024 | I12: =MONTH(Tabela1[[#This Row],[Data de Validade]]) -> 5 | J12: 88834 | K12: Panamá | N12: P915P867 | O12: =COUNTIFS(B:B,N12) -> 1 | R12: Sudeste | S12: =SUMIFS($J:$J,$K:$K, S$10, $D:$D, $R12) -> 37494439 | T12: =SUMIFS($J:$J,$K:$K, T$10, $D:$D, $R12) -> 38989407 | U12: =SUMIFS($J:$J,$K:$K, U$10, $D:$D, $R12) -> 38539749 | V12: =SUMIFS($J:$J,$K:$K, V$10, $D:$D, $R12) -> 37891952 | X12: Centro-Oeste | Y12: =COUNTIFS($K:$K, Y$9, $D:$D, $X12) -> 172 | Z12: =COUNTIFS($K:$K, Z$9, $D:$D, $X12) -> 133 | AA12: =COUNTIFS($K:$K, AA$9, $D:$D, $X12) -> 136 | AB12: =COUNTIFS($K:$K, AB$9, $D:$D, $X12) -> 141
A13: Motufidatu | B13: P318P546 | C13: MA | D13: =VLOOKUP(Tabela1[[#This Row],[Origem]], 'Perguntas 1 a 24'!$J$28:$K$34, 2, 0) -> Nordeste | E13: =Tabela1[[#This Row],[Descrição]]&"-"&Tabela1[[#This Row],[Código]]&"/"&Tabela1[[#This Row],[Origem]] -> Motufidatu-P318P546/MA | F13: 45427 | G13: {=_xlfn.IFS(AND(Tabela1[[#This Row],[Data de Validade]]<= DATE(2025, 12, 31), Tabela1[[#This Row],[Custo de Produção]]>50000), "Urgente e Caro", AND(Tabela1[[#This Row],[Data de Validade]]<= DATE(2025, 12, 31), Tabela1[[#This Row],[Custo de Produção]]<= 50000), "Urgente", AND(F13>= DATE(2026,1,1), F13<= DATE(2028, 12, 31), J13>50000), "Pendente e Caro", AND(F13>= DATE(2026,1,1), F13<= DATE(2028, 12, 31), J13<=50000), "Pendente", F13>= DATE(2029,1,1), "Não prioeitário")} -> Urgente e Caro | H13: =YEAR(Tabela1[[#This Row],[Data de Validade]]) -> 2024 | I13: =MONTH(Tabela1[[#This Row],[Data de Validade]]) -> 5 | J13: 87366 | K13: Espanha | N13: P318P546 | O13: =COUNTIFS(B:B,N13) -> 1 | R13: Centro-Oeste | S13: =SUMIFS($J:$J,$K:$K, S$10, $D:$D, $R13) -> 12025755 | T13: =SUMIFS($J:$J,$K:$K, T$10, $D:$D, $R13) -> 9401319 | U13: =SUMIFS($J:$J,$K:$K, U$10, $D:$D, $R13) -> 9133421 | V13: =SUMIFS($J:$J,$K:$K, V$10, $D:$D, $R13) -> 9935480 | X13: Norte | Y13: =COUNTIFS($K:$K, Y$9, $D:$D, $X13) -> 0 | Z13: =COUNTIFS($K:$K, Z$9, $D:$D, $X13) -> 0 | AA13: =COUNTIFS($K:$K, AA$9, $D:$D, $X13) -> 0 | AB13: =COUNTIFS($K:$K, AB$9, $D:$D, $X13) -> 0
A14: Cepeti | B14: P937P636 | C14: GO | D14: =VLOOKUP(Tabela1[[#This Row],[Origem]], 'Perguntas 1 a 24'!$J$28:$K$34, 2, 0) -> Centro-Oeste | E14: =Tabela1[[#This Row],[Descrição]]&"-"&Tabela1[[#This Row],[Código]]&"/"&Tabela1[[#This Row],[Origem]] -> Cepeti-P937P636/GO | F14: 45427 | G14: {=_xlfn.IFS(AND(Tabela1[[#This Row],[Data de Validade]]<= DATE(2025, 12, 31), Tabela1[[#This Row],[Custo de Produção]]>50000), "Urgente e Caro", AND(Tabela1[[#This Row],[Data de Validade]]<= DATE(2025, 12, 31), Tabela1[[#This Row],[Custo de Produção]]<= 50000), "Urgente", AND(F14>= DATE(2026,1,1), F14<= DATE(2028, 12, 31), J14>50000), "Pendente e Caro", AND(F14>= DATE(2026,1,1), F14<= DATE(2028, 12, 31), J14<=50000), "Pendente", F14>= DATE(2029,1,1), "Não prioeitário")} -> Urgente e Caro | H14: =YEAR(Tabela1[[#This Row],[Data de Validade]]) -> 2024 | I14: =MONTH(Tabela1[[#This Row],[Data de Validade]]) -> 5 | J14: 60456 | K14: Panamá | N14: P937P636 | O14: =COUNTIFS(B:B,N14) -> 1 | R14: Total | S14: =SUM(S11:S13) -> 71102637 | T14: =SUM(T11:T13) -> 66823089 | U14: =SUM(U11:U13) -> 67057272 | V14: =SUM(V11:V13) -> 67157220 | X14: Total | Y14: =SUM(Y10:Y13) -> 1007 | Z14: =SUM(Z10:Z13) -> 930 | AA14: =SUM(AA10:AA13) -> 958 | AB14: =SUM(AB10:AB13) -> 960
A15: Pudepa | B15: H586H551 | C15: AL | D15: =VLOOKUP(Tabela1[[#This Row],[Origem]], 'Perguntas 1 a 24'!$J$28:$K$34, 2, 0) -> Nordeste | E15: =Tabela1[[#This Row],[Descrição]]&"-"&Tabela1[[#This Row],[Código]]&"/"&Tabela1[[#This Row],[Origem]] -> Pudepa-H586H551/AL | F15: 45427 | G15: {=_xlfn.IFS(AND(Tabela1[[#This Row],[Data de Validade]]<= DATE(2025, 12, 31), Tabela1[[#This Row],[Custo de Produção]]>50000), "Urgente e Caro", AND(Tabela1[[#This Row],[Data de Validade]]<= DATE(2025, 12, 31), Tabela1[[#This Row],[Custo de Produção]]<= 50000), "Urgente", AND(F15>= DATE(2026,1,1), F15<= DATE(2028, 12, 31), J15>50000), "Pendente e Caro", AND(F15>= DATE(2026,1,1), F15<= DATE(2028, 12, 31), J15<=50000), "Pendente", F15>= DATE(2029,1,1), "Não prioeitário")} -> Urgente e Caro | H15: =YEAR(Tabela1[[#This Row],[Data de Validade]]) -> 2024 | I15: =MONTH(Tabela1[[#This Row],[Data de Validade]]) -> 5 | J15: 56807 | K15: Austrália | N15: H586H551 | O15: =COUNTIFS(B:B,N15) -> 1
A16: Cirefapu | B16: H824P368 | C16: SP | D16: =VLOOKUP(Tabela1[[#This Row],[Origem]], 'Perguntas 1 a 24'!$J$28:$K$34, 2, 0) -> Sudeste | E16: =Tabela1[[#This Row],[Descrição]]&"-"&Tabela1[[#This Row],[Código]]&"/"&Tabela1[[#This Row],[Origem]] -> Cirefapu-H824P368/SP | F16: 45428 | G16: {=_xlfn.IFS(AND(Tabela1[[#This Row],[Data de Validade]]<= DATE(2025, 12, 31), Tabela1[[#This Row],[Custo de Produção]]>50000), "Urgente e Caro", AND(Tabela1[[#This Row],[Data de Validade]]<= DATE(2025, 12, 31), Tabela1[[#This Row],[Custo de Produção]]<= 50000), "Urgente", AND(F16>= DATE(2026,1,1), F16<= DATE(2028, 12, 31), J16>50000), "Pendente e Caro", AND(F16>= DATE(2026,1,1), F16<= DATE(2028, 12, 31), J16<=50000), "Pendente", F16>= DATE(2029,1,1), "Não prioeitário")} -> Urgente e Caro | H16: =YEAR(Tabela1[[#This Row],[Data de Validade]]) -> 2024 | I16: =MONTH(Tabela1[[#This Row],[Data de Validade]]) -> 5 | J16: 65721 | K16: Panamá | N16: H824P368 | O16: =COUNTIFS(B:B,N16) -> 1 | R16: Qual o País que é maior em Qtd? E também em Valor de Custo?
A17: Netugo | B17: H149P458 | C17: ES | D17: =VLOOKUP(Tabela1[[#This Row],[Origem]], 'Perguntas 1 a 24'!$J$28:$K$34, 2, 0) -> Sudeste | E17: =Tabela1[[#This Row],[Descrição]]&"-"&Tabela1[[#This Row],[Código]]&"/"&Tabela1[[#This Row],[Origem]] -> Netugo-H149P458/ES | F17: 45429 | G17: {=_xlfn.IFS(AND(Tabela1[[#This Row],[Data de Validade]]<= DATE(2025, 12, 31), Tabela1[[#This Row],[Custo de Produção]]>50000), "Urgente e Caro", AND(Tabela1[[#This Row],[Data de Validade]]<= DATE(2025, 12, 31), Tabela1[[#This Row],[Custo de Produção]]<= 50000), "Urgente", AND(F17>= DATE(2026,1,1), F17<= DATE(2028, 12, 31), J17>50000), "Pendente e Caro", AND(F17>= DATE(2026,1,1), F17<= DATE(2028, 12, 31), J17<=50000), "Pendente", F17>= DATE(2029,1,1), "Não prioeitário")} -> Urgente e Caro | H17: =YEAR(Tabela1[[#This Row],[Data de Validade]]) -> 2024 | I17: =MONTH(Tabela1[[#This Row],[Data de Validade]]) -> 5 | J17: 53918 | K17: Holanda | N17: H149P458 | O17: =COUNTIFS(B:B,N17) -> 1 | R17: Quantidade | S17: {=INDEX(Y9:AB9, 0, MATCH(LARGE(Y14:AB14, 1), Y14:AB14, 0))} -> Austrália
A18: Pofodoge | B18: H985H461 | C18: RJ | D18: =VLOOKUP(Tabela1[[#This Row],[Origem]], 'Perguntas 1 a 24'!$J$28:$K$34, 2, 0) -> Sudeste | E18: =Tabela1[[#This Row],[Descrição]]&"-"&Tabela1[[#This Row],[Código]]&"/"&Tabela1[[#This Row],[Origem]] -> Pofodoge-H985H461/RJ | F18: 45429 | G18: {=_xlfn.IFS(AND(Tabela1[[#This Row],[Data de Validade]]<= DATE(2025, 12, 31), Tabela1[[#This Row],[Custo de Produção]]>50000), "Urgente e Caro", AND(Tabela1[[#This Row],[Data de Validade]]<= DATE(2025, 12, 31), Tabela1[[#This Row],[Custo de Produção]]<= 50000), "Urgente", AND(F18>= DATE(2026,1,1), F18<= DATE(2028, 12, 31), J18>50000), "Pendente e Caro", AND(F18>= DATE(2026,1,1), F18<= DATE(2028, 12, 31), J18<=50000), "Pendente", F18>= DATE(2029,1,1), "Não prioeitário")} -> Urgente | H18: =YEAR(Tabela1[[#This Row],[Data de Validade]]) -> 2024 | I18: =MONTH(Tabela1[[#This Row],[Data de Validade]]) -> 5 | J18: 27565 | K18: Panamá | N18: H985H461 | O18: =COUNTIFS(B:B,N18) -> 1 | R18: Valor | S18: {=INDEX(S10:V10, 0, MATCH(LARGE(S14:V14, 1), S14:V14, 0))} -> Austrália
B19: P561H622 | C19: ES | D19: =VLOOKUP(Tabela1[[#This Row],[Origem]], 'Perguntas 1 a 24'!$J$28:$K$34, 2, 0) -> Sudeste | E19: =Tabela1[[#This Row],[Descrição]]&"-"&Tabela1[[#This Row],[Código]]&"/"&Tabela1[[#This Row],[Origem]] -> -P561H622/ES | F19: 45430 | G19: {=_xlfn.IFS(AND(Tabela1[[#This Row],[Data de Validade]]<= DATE(2025, 12, 31), Tabela1[[#This Row],[Custo de Produção]]>50000), "Urgente e Caro", AND(Tabela1[[#This Row],[Data de Validade]]<= DATE(2025, 12, 31), Tabela1[[#This Row],[Custo de Produção]]<= 50000), "Urgente", AND(F19>= DATE(2026,1,1), F19<= DATE(2028, 12, 31), J19>50000), "Pendente e Caro", AND(F19>= DATE(2026,1,1), F19<= DATE(2028, 12, 31), J19<=50000), "Pendente", F19>= DATE(2029,1,1), "Não prioeitário")} -> Urgente e Caro | H19: =YEAR(Tabela1[[#This Row],[Data de Validade]]) -> 2024 | I19: =MONTH(Tabela1[[#This Row],[Data de Validade]]) -> 5 | J19: 51114 | K19: Panamá | N19: P561H622 | O19: =COUNTIFS(B:B,N19) -> 1
A20: Limalegado | B20: H635H414 | C20: AL | D20: =VLOOKUP(Tabela1[[#This Row],[Origem]], 'Perguntas 1 a 24'!$J$28:$K$34, 2, 0) -> Nordeste | E20: =Tabela1[[#This Row],[Descrição]]&"-"&Tabela1[[#This Row],[Código]]&"/"&Tabela1[[#This Row],[Origem]] -> Limalegado-H635H414/AL | F20: 45431 | G20: {=_xlfn.IFS(AND(Tabela1[[#This Row],[Data de Validade]]<= DATE(2025, 12, 31), Tabela1[[#This Row],[Custo de Produção]]>50000), "Urgente e Caro", AND(Tabela1[[#This Row],[Data de Validade]]<= DATE(2025, 12, 31), Tabela1[[#This Row],[Custo de Produção]]<= 50000), "Urgente", AND(F20>= DATE(2026,1,1), F20<= DATE(2028, 12, 31), J20>50000), "Pendente e Caro", AND(F20>= DATE(2026,1,1), F20<= DATE(2028, 12, 31), J20<=50000), "Pendente", F20>= DATE(2029,1,1), "Não prioeitário")} -> Urgente | H20: =YEAR(Tabela1[[#This Row],[Data de Validade]]) -> 2024 | I20: =MONTH(Tabela1[[#This Row],[Data de Validade]]) -> 5 | J20: 41665 | K20: Austrália | N20: H635H414 | O20: =COUNTIFS(B:B,N20) -> 1
A21: Tepogigiro | B21: H877P957 | C21: MG | D21: =VLOOKUP(Tabela1[[#This Row],[Origem]], 'Perguntas 1 a 24'!$J$28:$K$34, 2, 0) -> Sudeste | E21: =Tabela1[[#This Row],[Descrição]]&"-"&Tabela1[[#This Row],[Código]]&"/"&Tabela1[[#This Row],[Origem]] -> Tepogigiro-H877P957/MG | F21: 45433 | G21: {=_xlfn.IFS(AND(Tabela1[[#This Row],[Data de Validade]]<= DATE(2025, 12, 31), Tabela1[[#This Row],[Custo de Produção]]>50000), "Urgente e Caro", AND(Tabela1[[#This Row],[Data de Validade]]<= DATE(2025, 12, 31), Tabela1[[#This Row],[Custo de Produção]]<= 50000), "Urgente", AND(F21>= DATE(2026,1,1), F21<= DATE(2028, 12, 31), J21>50000), "Pendente e Caro", AND(F21>= DATE(2026,1,1), F21<= DATE(2028, 12, 31), J21<=50000), "Pendente", F21>= DATE(2029,1,1), "Não prioeitário")} -> Urgente e Caro | H21: =YEAR(Tabela1[[#This Row],[Data de Validade]]) -> 2024 | I21: =MONTH(Tabela1[[#This Row],[Data de Validade]]) -> 5 | J21: 87845 | K21: Austrália | N21: H877P957 | O21: =COUNTIFS(B:B,N21) -> 1
A22: Natavi | B22: P767H833 | C22: SP | D22: =VLOOKUP(Tabela1[[#This Row],[Origem]], 'Perguntas 1 a 24'!$J$28:$K$34, 2, 0) -> Sudeste | E22: =Tabela1[[#This Row],[Descrição]]&"-"&Tabela1[[#This Row],[Código]]&"/"&Tabela1[[#This Row],[Origem]] -> Natavi-P767H833/SP | F22: 45433 | G22: {=_xlfn.IFS(AND(Tabela1[[#This Row],[Data de Validade]]<= DATE(2025, 12, 31), Tabela1[[#This Row],[Custo de Produção]]>50000), "Urgente e Caro", AND(Tabela1[[#This Row],[Data de Validade]]<= DATE(2025, 12, 31), Tabela1[[#This Row],[Custo de Produção]]<= 50000), "Urgente", AND(F22>= DATE(2026,1,1), F22<= DATE(2028, 12, 31), J22>50000), "Pendente e Caro", AND(F22>= DATE(2026,1,1), F22<= DATE(2028, 12, 31), J22<=50000), "Pendente", F22>= DATE(2029,1,1), "Não prioeitário")} -> Urgente e Caro | H22: =YEAR(Tabela1[[#This Row],[Data de Validade]]) -> 2024 | I22: =MONTH(Tabela1[[#This Row],[Data de Validade]]) -> 5 | J22: 50593 | K22: Holanda | N22: P767H833 | O22: =COUNTIFS(B:B,N22) -> 1 | S22: Análise dos Top 5 que tiveram maiores Custos de Produção
A23: Mafune | B23: P472P981 | C23: GO | D23: =VLOOKUP(Tabela1[[#This Row],[Origem]], 'Perguntas 1 a 24'!$J$28:$K$34, 2, 0) -> Centro-Oeste | E23: =Tabela1[[#This Row],[Descrição]]&"-"&Tabela1[[#This Row],[Código]]&"/"&Tabela1[[#This Row],[Origem]] -> Mafune-P472P981/GO | F23: 45434 | G23: {=_xlfn.IFS(AND(Tabela1[[#This Row],[Data de Validade]]<= DATE(2025, 12, 31), Tabela1[[#This Row],[Custo de Produção]]>50000), "Urgente e Caro", AND(Tabela1[[#This Row],[Data de Validade]]<= DATE(2025, 12, 31), Tabela1[[#This Row],[Custo de Produção]]<= 50000), "Urgente", AND(F23>= DATE(2026,1,1), F23<= DATE(2028, 12, 31), J23>50000), "Pendente e Caro", AND(F23>= DATE(2026,1,1), F23<= DATE(2028, 12, 31), J23<=50000), "Pendente", F23>= DATE(2029,1,1), "Não prioeitário")} -> Urgente e Caro | H23: =YEAR(Tabela1[[#This Row],[Data de Validade]]) -> 2024 | I23: =MONTH(Tabela1[[#This Row],[Data de Validade]]) -> 5 | J23: 78874 | K23: Espanha | N23: P472P981 | O23: =COUNTIFS(B:B,N23) -> 1 | R23: TOP 5 | S23: Descrição | T23: Código | U23: Custo de Produção | V23: País de Destino
A24: Pevupetiti | B24: H124P283 | C24: MA | D24: =VLOOKUP(Tabela1[[#This Row],[Origem]], 'Perguntas 1 a 24'!$J$28:$K$34, 2, 0) -> Nordeste | E24: =Tabela1[[#This Row],[Descrição]]&"-"&Tabela1[[#This Row],[Código]]&"/"&Tabela1[[#This Row],[Origem]] -> Pevupetiti-H124P283/MA | F24: 45434 | G24: {=_xlfn.IFS(AND(Tabela1[[#This Row],[Data de Validade]]<= DATE(2025, 12, 31), Tabela1[[#This Row],[Custo de Produção]]>50000), "Urgente e Caro", AND(Tabela1[[#This Row],[Data de Validade]]<= DATE(2025, 12, 31), Tabela1[[#This Row],[Custo de Produção]]<= 50000), "Urgente", AND(F24>= DATE(2026,1,1), F24<= DATE(2028, 12, 31), J24>50000), "Pendente e Caro", AND(F24>= DATE(2026,1,1), F24<= DATE(2028, 12, 31), J24<=50000), "Pendente", F24>= DATE(2029,1,1), "Não prioeitário")} -> Urgente | H24: =YEAR(Tabela1[[#This Row],[Data de Validade]]) -> 2024 | I24: =MONTH(Tabela1[[#This Row],[Data de Validade]]) -> 5 | J24: 41981 | K24: Panamá | N24: H124P283 | O24: =COUNTIFS(B:B,N24) -> 1 | R24: 1 | S24: =INDEX(A:A, MATCH(LARGE(J:J, R24),J:J, 0)) -> Vutufe | T24: =INDEX(B:B, MATCH(LARGE(J:J,R24),J:J, 0)) -> P873H963 | U24: {=INDEX(J:J, MATCH(LARGE(J:J, R24), J:J,0), 0)} -> 119945 | V24: {=INDEX(K:K, MATCH(LARGE(J:J, R24),J:J, 0), 0)} -> Panamá
A25: Vapotudi | B25: P716H775 | C25: AL | D25: =VLOOKUP(Tabela1[[#This Row],[Origem]], 'Perguntas 1 a 24'!$J$28:$K$34, 2, 0) -> Nordeste | E25: =Tabela1[[#This Row],[Descrição]]&"-"&Tabela1[[#This Row],[Código]]&"/"&Tabela1[[#This Row],[Origem]] -> Vapotudi-P716H775/AL | F25: 45434 | G25: {=_xlfn.IFS(AND(Tabela1[[#This Row],[Data de Validade]]<= DATE(2025, 12, 31), Tabela1[[#This Row],[Custo de Produção]]>50000), "Urgente e Caro", AND(Tabela1[[#This Row],[Data de Validade]]<= DATE(2025, 12, 31), Tabela1[[#This Row],[Custo de Produção]]<= 50000), "Urgente", AND(F25>= DATE(2026,1,1), F25<= DATE(2028, 12, 31), J25>50000), "Pendente e Caro", AND(F25>= DATE(2026,1,1), F25<= DATE(2028, 12, 31), J25<=50000), "Pendente", F25>= DATE(2029,1,1), "Não prioeitário")} -> Urgente | H25: =YEAR(Tabela1[[#This Row],[Data de Validade]]) -> 2024 | I25: =MONTH(Tabela1[[#This Row],[Data de Validade]]) -> 5 | J25: 24458 | K25: Austrália | N25: P716H775 | O25: =COUNTIFS(B:B,N25) -> 1 | R25: 2 | S25: =INDEX(A:A, MATCH(LARGE(J:J, R25),J:J, 0)) -> Licapiro | T25: =INDEX(B:B, MATCH(LARGE(J:J,R25),J:J, 0)) -> H948H323 | U25: {=INDEX(J:J, MATCH(LARGE(J:J, R25), J:J,0), 0)} -> 119933 | V25: {=INDEX(K:K, MATCH(LARGE(J:J, R25),J:J, 0), 0)} -> Austrália
A26: Pavaputi | B26: P441H685 | C26: MA | D26: =VLOOKUP(Tabela1[[#This Row],[Origem]], 'Perguntas 1 a 24'!$J$28:$K$34, 2, 0) -> Nordeste | E26: =Tabela1[[#This Row],[Descrição]]&"-"&Tabela1[[#This Row],[Código]]&"/"&Tabela1[[#This Row],[Origem]] -> Pavaputi-P441H685/MA | F26: 45435 | G26: {=_xlfn.IFS(AND(Tabela1[[#This Row],[Data de Validade]]<= DATE(2025, 12, 31), Tabela1[[#This Row],[Custo de Produção]]>50000), "Urgente e Caro", AND(Tabela1[[#This Row],[Data de Validade]]<= DATE(2025, 12, 31), Tabela1[[#This Row],[Custo de Produção]]<= 50000), "Urgente", AND(F26>= DATE(2026,1,1), F26<= DATE(2028, 12, 31), J26>50000), "Pendente e Caro", AND(F26>= DATE(2026,1,1), F26<= DATE(2028, 12, 31), J26<=50000), "Pendente", F26>= DATE(2029,1,1), "Não prioeitário")} -> Urgente e Caro | H26: =YEAR(Tabela1[[#This Row],[Data de Validade]]) -> 2024 | I26: =MONTH(Tabela1[[#This Row],[Data de Validade]]) -> 5 | J26: 114895 | K26: Panamá | N26: P441H685 | O26: =COUNTIFS(B:B,N26) -> 1 | R26: 3 | S26: =INDEX(A:A, MATCH(LARGE(J:J, R26),J:J, 0)) -> Gopenemo | T26: =INDEX(B:B, MATCH(LARGE(J:J,R26),J:J, 0)) -> H155P441 | U26: {=INDEX(J:J, MATCH(LARGE(J:J, R26), J:J,0), 0)} -> 119903 | V26: {=INDEX(K:K, MATCH(LARGE(J:J, R26),J:J, 0), 0)} -> Austrália
A27: Varive | B27: H867P288 | C27: AL | D27: =VLOOKUP(Tabela1[[#This Row],[Origem]], 'Perguntas 1 a 24'!$J$28:$K$34, 2, 0) -> Nordeste | E27: =Tabela1[[#This Row],[Descrição]]&"-"&Tabela1[[#This Row],[Código]]&"/"&Tabela1[[#This Row],[Origem]] -> Varive-H867P288/AL | F27: 45435 | G27: {=_xlfn.IFS(AND(Tabela1[[#This Row],[Data de Validade]]<= DATE(2025, 12, 31), Tabela1[[#This Row],[Custo de Produção]]>50000), "Urgente e Caro", AND(Tabela1[[#This Row],[Data de Validade]]<= DATE(2025, 12, 31), Tabela1[[#This Row],[Custo de Produção]]<= 50000), "Urgente", AND(F27>= DATE(2026,1,1), F27<= DATE(2028, 12, 31), J27>50000), "Pendente e Caro", AND(F27>= DATE(2026,1,1), F27<= DATE(2028, 12, 31), J27<=50000), "Pendente", F27>= DATE(2029,1,1), "Não prioeitário")} -> Urgente e Caro | H27: =YEAR(Tabela1[[#This Row],[Data de Validade]]) -> 2024 | I27: =MONTH(Tabela1[[#This Row],[Data de Validade]]) -> 5 | J27: 62600 | K27: Panamá | N27: H867P288 | O27: =COUNTIFS(B:B,N27) -> 1 | R27: 4 | S27: =INDEX(A:A, MATCH(LARGE(J:J, R27),J:J, 0)) -> Petitode | T27: =INDEX(B:B, MATCH(LARGE(J:J,R27),J:J, 0)) -> H119P473 | U27: {=INDEX(J:J, MATCH(LARGE(J:J, R27), J:J,0), 0)} -> 119901 | V27: {=INDEX(K:K, MATCH(LARGE(J:J, R27),J:J, 0), 0)} -> Austrália
A28: Momupa | B28: P892H748 | C28: ES | D28: =VLOOKUP(Tabela1[[#This Row],[Origem]], 'Perguntas 1 a 24'!$J$28:$K$34, 2, 0) -> Sudeste | E28: =Tabela1[[#This Row],[Descrição]]&"-"&Tabela1[[#This Row],[Código]]&"/"&Tabela1[[#This Row],[Origem]] -> Momupa-P892H748/ES | F28: 45436 | G28: {=_xlfn.IFS(AND(Tabela1[[#This Row],[Data de Validade]]<= DATE(2025, 12, 31), Tabela1[[#This Row],[Custo de Produção]]>50000), "Urgente e Caro", AND(Tabela1[[#This Row],[Data de Validade]]<= DATE(2025, 12, 31), Tabela1[[#This Row],[Custo de Produção]]<= 50000), "Urgente", AND(F28>= DATE(2026,1,1), F28<= DATE(2028, 12, 31), J28>50000), "Pendente e Caro", AND(F28>= DATE(2026,1,1), F28<= DATE(2028, 12, 31), J28<=50000), "Pendente", F28>= DATE(2029,1,1), "Não prioeitário")} -> Urgente e Caro | H28: =YEAR(Tabela1[[#This Row],[Data de Validade]]) -> 2024 | I28: =MONTH(Tabela1[[#This Row],[Data de Validade]]) -> 5 | J28: 75024 | K28: Espanha | N28: P892H748 | O28: =COUNTIFS(B:B,N28) -> 1 | R28: 5 | S28: =INDEX(A:A, MATCH(LARGE(J:J, R28),J:J, 0)) -> Vigopurutu | T28: =INDEX(B:B, MATCH(LARGE(J:J,R28),J:J, 0)) -> H776P365 | U28: {=INDEX(J:J, MATCH(LARGE(J:J, R28), J:J,0), 0)} -> 119889 | V28: {=INDEX(K:K, MATCH(LARGE(J:J, R28),J:J, 0), 0)} -> Panamá
A29: Retorago | B29: H872P394 | C29: GO | D29: =VLOOKUP(Tabela1[[#This Row],[Origem]], 'Perguntas 1 a 24'!$J$28:$K$34, 2, 0) -> Centro-Oeste | E29: =Tabela1[[#This Row],[Descrição]]&"-"&Tabela1[[#This Row],[Código]]&"/"&Tabela1[[#This Row],[Origem]] -> Retorago-H872P394/GO | F29: 45437 | G29: {=_xlfn.IFS(AND(Tabela1[[#This Row],[Data de Validade]]<= DATE(2025, 12, 31), Tabela1[[#This Row],[Custo de Produção]]>50000), "Urgente e Caro", AND(Tabela1[[#This Row],[Data de Validade]]<= DATE(2025, 12, 31), Tabela1[[#This Row],[Custo de Produção]]<= 50000), "Urgente", AND(F29>= DATE(2026,1,1), F29<= DATE(2028, 12, 31), J29>50000), "Pendente e Caro", AND(F29>= DATE(2026,1,1), F29<= DATE(2028, 12, 31), J29<=50000), "Pendente", F29>= DATE(2029,1,1), "Não prioeitário")} -> Urgente e Caro | H29: =YEAR(Tabela1[[#This Row],[Data de Validade]]) -> 2024 | I29: =MONTH(Tabela1[[#This Row],[Data de Validade]]) -> 5 | J29: 86978 | K29: Espanha | N29: H872P394 | O29: =COUNTIFS(B:B,N29) -> 1
A30: Vicofegu | B30: H186H326 | C30: GO | D30: =VLOOKUP(Tabela1[[#This Row],[Origem]], 'Perguntas 1 a 24'!$J$28:$K$34, 2, 0) -> Centro-Oeste | E30: =Tabela1[[#This Row],[Descrição]]&"-"&Tabela1[[#This Row],[Código]]&"/"&Tabela1[[#This Row],[Origem]] -> Vicofegu-H186H326/GO | F30: 45437 | G30: {=_xlfn.IFS(AND(Tabela1[[#This Row],[Data de Validade]]<= DATE(2025, 12, 31), Tabela1[[#This Row],[Custo de Produção]]>50000), "Urgente e Caro", AND(Tabela1[[#This Row],[Data de Validade]]<= DATE(2025, 12, 31), Tabela1[[#This Row],[Custo de Produção]]<= 50000), "Urgente", AND(F30>= DATE(2026,1,1), F30<= DATE(2028, 12, 31), J30>50000), "Pendente e Caro", AND(F30>= DATE(2026,1,1), F30<= DATE(2028, 12, 31), J30<=50000), "Pendente", F30>= DATE(2029,1,1), "Não prioeitário")} -> Urgente | H30: =YEAR(Tabela1[[#This Row],[Data de Validade]]) -> 2024 | I30: =MONTH(Tabela1[[#This Row],[Data de Validade]]) -> 5 | J30: 36787 | K30: Holanda | N30: H186H326 | O30: =COUNTIFS(B:B,N30) -> 1
A31: Paleropu | B31: H611P813 | C31: GO | D31: =VLOOKUP(Tabela1[[#This Row],[Origem]], 'Perguntas 1 a 24'!$J$28:$K$34, 2, 0) -> Centro-Oeste | E31: =Tabela1[[#This Row],[Descrição]]&"-"&Tabela1[[#This Row],[Código]]&"/"&Tabela1[[#This Row],[Origem]] -> Paleropu-H611P813/GO | F31: 45438 | G31: {=_xlfn.IFS(AND(Tabela1[[#This Row],[Data de Validade]]<= DATE(2025, 12, 31), Tabela1[[#This Row],[Custo de Produção]]>50000), "Urgente e Caro", AND(Tabela1[[#This Row],[Data de Validade]]<= DATE(2025, 12, 31), Tabela1[[#This Row],[Custo de Produção]]<= 50000), "Urgente", AND(F31>= DATE(2026,1,1), F31<= DATE(2028, 12, 31), J31>50000), "Pendente e Caro", AND(F31>= DATE(2026,1,1), F31<= DATE(2028, 12, 31), J31<=50000), "Pendente", F31>= DATE(2029,1,1), "Não prioeitário")} -> Urgente e Caro | H31: =YEAR(Tabela1[[#This Row],[Data de Validade]]) -> 2024 | I31: =MONTH(Tabela1[[#This Row],[Data de Validade]]) -> 5 | J31: 114045 | K31: Espanha | N31: H611P813 | O31: =COUNTIFS(B:B,N31) -> 1
A32: Teterifipa | B32: P876H266 | C32: SP | D32: =VLOOKUP(Tabela1[[#This Row],[Origem]], 'Perguntas 1 a 24'!$J$28:$K$34, 2, 0) -> Sudeste | E32: =Tabela1[[#This Row],[Descrição]]&"-"&Tabela1[[#This Row],[Código]]&"/"&Tabela1[[#This Row],[Origem]] -> Teterifipa-P876H266/SP | F32: 45438 | G32: {=_xlfn.IFS(AND(Tabela1[[#This Row],[Data de Validade]]<= DATE(2025, 12, 31), Tabela1[[#This Row],[Custo de Produção]]>50000), "Urgente e Caro", AND(Tabela1[[#This Row],[Data de Validade]]<= DATE(2025, 12, 31), Tabela1[[#This Row],[Custo de Produção]]<= 50000), "Urgente", AND(F32>= DATE(2026,1,1), F32<= DATE(2028, 12, 31), J32>50000), "Pendente e Caro", AND(F32>= DATE(2026,1,1), F32<= DATE(2028, 12, 31), J32<=50000), "Pendente", F32>= DATE(2029,1,1), "Não prioeitário")} -> Urgente e Caro | H32: =YEAR(Tabela1[[#This Row],[Data de Validade]]) -> 2024 | I32: =MONTH(Tabela1[[#This Row],[Data de Validade]]) -> 5 | J32: 90122 | K32: Espanha | N32: P876H266 | O32: =COUNTIFS(B:B,N32) -> 1
A33: Tupagada | B33: P422H219 | C33: SP | D33: =VLOOKUP(Tabela1[[#This Row],[Origem]], 'Perguntas 1 a 24'!$J$28:$K$34, 2, 0) -> Sudeste | E33: =Tabela1[[#This Row],[Descrição]]&"-"&Tabela1[[#This Row],[Código]]&"/"&Tabela1[[#This Row],[Origem]] -> Tupagada-P422H219/SP | F33: 45438 | G33: {=_xlfn.IFS(AND(Tabela1[[#This Row],[Data de Validade]]<= DATE(2025, 12, 31), Tabela1[[#This Row],[Custo de Produção]]>50000), "Urgente e Caro", AND(Tabela1[[#This Row],[Data de Validade]]<= DATE(2025, 12, 31), Tabela1[[#This Row],[Custo de Produção]]<= 50000), "Urgente", AND(F33>= DATE(2026,1,1), F33<= DATE(2028, 12, 31), J33>50000), "Pendente e Caro", AND(F33>= DATE(2026,1,1), F33<= DATE(2028, 12, 31), J33<=50000), "Pendente", F33>= DATE(2029,1,1), "Não prioeitário")} -> Urgente | H33: =YEAR(Tabela1[[#This Row],[Data de Validade]]) -> 2024 | I33: =MONTH(Tabela1[[#This Row],[Data de Validade]]) -> 5 | J33: 35450 | K33: Panamá | N33: P422H219 | O33: =COUNTIFS(B:B,N33) -> 1
A34: Porepore | B34: P873P382 | C34: SP | D34: =VLOOKUP(Tabela1[[#This Row],[Origem]], 'Perguntas 1 a 24'!$J$28:$K$34, 2, 0) -> Sudeste | E34: =Tabela1[[#This Row],[Descrição]]&"-"&Tabela1[[#This Row],[Código]]&"/"&Tabela1[[#This Row],[Origem]] -> Porepore-P873P382/SP | F34: 45441 | G34: {=_xlfn.IFS(AND(Tabela1[[#This Row],[Data de Validade]]<= DATE(2025, 12, 31), Tabela1[[#This Row],[Custo de Produção]]>50000), "Urgente e Caro", AND(Tabela1[[#This Row],[Data de Validade]]<= DATE(2025, 12, 31), Tabela1[[#This Row],[Custo de Produção]]<= 50000), "Urgente", AND(F34>= DATE(2026,1,1), F34<= DATE(2028, 12, 31), J34>50000), "Pendente e Caro", AND(F34>= DATE(2026,1,1), F34<= DATE(2028, 12, 31), J34<=50000), "Pendente", F34>= DATE(2029,1,1), "Não prioeitário")} -> Urgente e Caro | H34: =YEAR(Tabela1[[#This Row],[Data de Validade]]) -> 2024 | I34: =MONTH(Tabela1[[#This Row],[Data de Validade]]) -> 5 | J34: 103488 | K34: Austrália | N34: P873P382 | O34: =COUNTIFS(B:B,N34) -> 1
A35: Tacicopo | B35: P561P729 | C35: SP | D35: =VLOOKUP(Tabela1[[#This Row],[Origem]], 'Perguntas 1 a 24'!$J$28:$K$34, 2, 0) -> Sudeste | E35: =Tabela1[[#This Row],[Descrição]]&"-"&Tabela1[[#This Row],[Código]]&"/"&Tabela1[[#This Row],[Origem]] -> Tacicopo-P561P729/SP | F35: 45442 | G35: {=_xlfn.IFS(AND(Tabela1[[#This Row],[Data de Validade]]<= DATE(2025, 12, 31), Tabela1[[#This Row],[Custo de Produção]]>50000), "Urgente e Caro", AND(Tabela1[[#This Row],[Data de Validade]]<= DATE(2025, 12, 31), Tabela1[[#This Row],[Custo de Produção]]<= 50000), "Urgente", AND(F35>= DATE(2026,1,1), F35<= DATE(2028, 12, 31), J35>50000), "Pendente e Caro", AND(F35>= DATE(2026,1,1), F35<= DATE(2028, 12, 31), J35<=50000), "Pendente", F35>= DATE(2029,1,1), "Não prioeitário")} -> Urgente e Caro | H35: =YEAR(Tabela1[[#This Row],[Data de Validade]]) -> 2024 | I35: =MONTH(Tabela1[[#This Row],[Data de Validade]]) -> 5 | J35: 68472 | K35: Espanha | N35: P561P729 | O35: =COUNTIFS(B:B,N35) -> 1
A36: Macirori | B36: H925H857 | C36: RJ | D36: =VLOOKUP(Tabela1[[#This Row],[Origem]], 'Perguntas 1 a 24'!$J$28:$K$34, 2, 0) -> Sudeste | E36: =Tabela1[[#This Row],[Descrição]]&"-"&Tabela1[[#This Row],[Código]]&"/"&Tabela1[[#This Row],[Origem]] -> Macirori-H925H857/RJ | F36: 45442 | G36: {=_xlfn.IFS(AND(Tabela1[[#This Row],[Data de Validade]]<= DATE(2025, 12, 31), Tabela1[[#This Row],[Custo de Produção]]>50000), "Urgente e Caro", AND(Tabela1[[#This Row],[Data de Validade]]<= DATE(2025, 12, 31), Tabela1[[#This Row],[Custo de Produção]]<= 50000), "Urgente", AND(F36>= DATE(2026,1,1), F36<= DATE(2028, 12, 31), J36>50000), "Pendente e Caro", AND(F36>= DATE(2026,1,1), F36<= DATE(2028, 12, 31), J36<=50000), "Pendente", F36>= DATE(2029,1,1), "Não prioeitário")} -> Urgente | H36: =YEAR(Tabela1[[#This Row],[Data de Validade]]) -> 2024 | I36: =MONTH(Tabela1[[#This Row],[Data de Validade]]) -> 5 | J36: 22772 | K36: Panamá | N36: H925H857 | O36: =COUNTIFS(B:B,N36) -> 1
A37: Pavifepo | B37: H499P514 | C37: MA | D37: =VLOOKUP(Tabela1[[#This Row],[Origem]], 'Perguntas 1 a 24'!$J$28:$K$34, 2, 0) -> Nordeste | E37: =Tabela1[[#This Row],[Descrição]]&"-"&Tabela1[[#This Row],[Código]]&"/"&Tabela1[[#This Row],[Origem]] -> Pavifepo-H499P514/MA | F37: 45443 | G37: {=_xlfn.IFS(AND(Tabela1[[#This Row],[Data de Validade]]<= DATE(2025, 12, 31), Tabela1[[#This Row],[Custo de Produção]]>50000), "Urgente e Caro", AND(Tabela1[[#This Row],[Data de Validade]]<= DATE(2025, 12, 31), Tabela1[[#This Row],[Custo de Produção]]<= 50000), "Urgente", AND(F37>= DATE(2026,1,1), F37<= DATE(2028, 12, 31), J37>50000), "Pendente e Caro", AND(F37>= DATE(2026,1,1), F37<= DATE(2028, 12, 31), J37<=50000), "Pendente", F37>= DATE(2029,1,1), "Não prioeitário")} -> Urgente | H37: =YEAR(Tabela1[[#This Row],[Data de Validade]]) -> 2024 | I37: =MONTH(Tabela1[[#This Row],[Data de Validade]]) -> 5 | J37: 43230 | K37: Holanda | N37: H499P514 | O37: =COUNTIFS(B:B,N37) -> 1
A38: Feleforu | B38: H749P458 | C38: GO | D38: =VLOOKUP(Tabela1[[#This Row],[Origem]], 'Perguntas 1 a 24'!$J$28:$K$34, 2, 0) -> Centro-Oeste | E38: =Tabela1[[#This Row],[Descrição]]&"-"&Tabela1[[#This Row],[Código]]&"/"&Tabela1[[#This Row],[Origem]] -> Feleforu-H749P458/GO | F38: 45444 | G38: {=_xlfn.IFS(AND(Tabela1[[#This Row],[Data de Validade]]<= DATE(2025, 12, 31), Tabela1[[#This Row],[Custo de Produção]]>50000), "Urgente e Caro", AND(Tabela1[[#This Row],[Data de Validade]]<= DATE(2025, 12, 31), Tabela1[[#This Row],[Custo de Produção]]<= 50000), "Urgente", AND(F38>= DATE(2026,1,1), F38<= DATE(2028, 12, 31), J38>50000), "Pendente e Caro", AND(F38>= DATE(2026,1,1), F38<= DATE(2028, 12, 31), J38<=50000), "Pendente", F38>= DATE(2029,1,1), "Não prioeitário")} -> Urgente | H38: =YEAR(Tabela1[[#This Row],[Data de Validade]]) -> 2024 | I38: =MONTH(Tabela1[[#This Row],[Data de Validade]]) -> 6 | J38: 44180 | K38: Panamá | N38: H749P458 | O38: =COUNTIFS(B:B,N38) -> 1
A39: Puvoca | B39: P379H325 | C39: GO | D39: =VLOOKUP(Tabela1[[#This Row],[Origem]], 'Perguntas 1 a 24'!$J$28:$K$34, 2, 0) -> Centro-Oeste | E39: =Tabela1[[#This Row],[Descrição]]&"-"&Tabela1[[#This Row],[Código]]&"/"&Tabela1[[#This Row],[Origem]] -> Puvoca-P379H325/GO | F39: 45445 | G39: {=_xlfn.IFS(AND(Tabela1[[#This Row],[Data de Validade]]<= DATE(2025, 12, 31), Tabela1[[#This Row],[Custo de Produção]]>50000), "Urgente e Caro", AND(Tabela1[[#This Row],[Data de Validade]]<= DATE(2025, 12, 31), Tabela1[[#This Row],[Custo de Produção]]<= 50000), "Urgente", AND(F39>= DATE(2026,1,1), F39<= DATE(2028, 12, 31), J39>50000), "Pendente e Caro", AND(F39>= DATE(2026,1,1), F39<= DATE(2028, 12, 31), J39<=50000), "Pendente", F39>= DATE(2029,1,1), "Não prioeitário")} -> Urgente e Caro | H39: =YEAR(Tabela1[[#This Row],[Data de Validade]]) -> 2024 | I39: =MONTH(Tabela1[[#This Row],[Data de Validade]]) -> 6 | J39: 112672 | K39: Holanda | N39: P379H325 | O39: =COUNTIFS(B:B,N39) -> 1
A40: Gurolicale | B40: H985H459 | C40: MG | D40: =VLOOKUP(Tabela1[[#This Row],[Origem]], 'Perguntas 1 a 24'!$J$28:$K$34, 2, 0) -> Sudeste | E40: =Tabela1[[#This Row],[Descrição]]&"-"&Tabela1[[#This Row],[Código]]&"/"&Tabela1[[#This Row],[Origem]] -> Gurolicale-H985H459/MG | F40: 45445 | G40: {=_xlfn.IFS(AND(Tabela1[[#This Row],[Data de Validade]]<= DATE(2025, 12, 31), Tabela1[[#This Row],[Custo de Produção]]>50000), "Urgente e Caro", AND(Tabela1[[#This Row],[Data de Validade]]<= DATE(2025, 12, 31), Tabela1[[#This Row],[Custo de Produção]]<= 50000), "Urgente", AND(F40>= DATE(2026,1,1), F40<= DATE(2028, 12, 31), J40>50000), "Pendente e Caro", AND(F40>= DATE(2026,1,1), F40<= DATE(2028, 12, 31), J40<=50000), "Pendente", F40>= DATE(2029,1,1), "Não prioeitário")} -> Urgente e Caro | H40: =YEAR(Tabela1[[#This Row],[Data de Validade]]) -> 2024 | I40: =MONTH(Tabela1[[#This Row],[Data de Validade]]) -> 6 | J40: 105592 | K40: Espanha | N40: H985H459 | O40: =COUNTIFS(B:B,N40) -> 1
...

Sheet Perguntas 1 a 24
C2: Separe as informações da base, deixando cada campo em uma coluna. Oculte as linhas de grade da planilha | J2: Crie na base de dados uma coluna com a chave do produto. Essa chave será a junção do código do produto, seu nome e estado de origem no seguinte formato: nome-código/origem. Por exemplo, o produto de nome Nocogifo, código P931H285 e origem MA terá a chave Nocogifo-P931H285/MA
C5: Formate a base de dados, aplicando formatação de moeda e de data abreviada nas colunas que se adequam. Ajuste também a largura das colunas e as cores das células: o preenchimento da primeira linha deve ser azul, o preenchimento das demais linhas será cinza e a cor da fonte de todas as linhas será preta. Use os tons das células abaixo:
J6: Na Base 1 existem códigos que aparecem mais do que uma vez na lista. Qual é o número máximo de aparições de um mesmo código na lista?
J9: =MAX('Base de Dados'!O:O) -> 6
E10: Fonte
J11: Qual a descrição, origem e data de validade dos 8 códigos abaixo? Não faça qualquer alteração na base de dados para responder essa pergunta. Caso algum código não seja encontrado, exibir a mensagem "não encontrado".
C12: O que é necessário para adicionar uma segmentação de dados nessa base de dados sem o uso de tabela dinâmica?
J14: Código | K14: Data de Validade | L14: Origem | M14: Descrição
C15: Formate a base como tabela, sem perder a formatação aplicada no exercício dois. | J15: H485H921 | K15: =_xlfn.XLOOKUP($J15,Tabela1[Código], Tabela1[Data de Validade],"Não",0) -> 46319 | L15: =_xlfn.XLOOKUP(J15,'Base de Dados'!B:B, 'Base de Dados'!C:C,"Não",0) -> RJ | M15: =_xlfn.XLOOKUP($J15, 'Base de Dados'!B:B, 'Base de Dados'!A:A, "Não", 0) -> Malari
J16: P469P428 | K16: =_xlfn.XLOOKUP($J16,Tabela1[Código], Tabela1[Data de Validade],"Não",0) -> 47476 | L16: =_xlfn.XLOOKUP(J16,'Base de Dados'!B:B, 'Base de Dados'!C:C,"Não",0) -> RJ | M16: =_xlfn.XLOOKUP($J16, 'Base de Dados'!B:B, 'Base de Dados'!A:A, "Não", 0) -> Tipafa
C17: Adicione uma formatação condicional de semáforo, colocando sinal vermelho quando custo de produção for maior que R$100.000, sinal amarelo com custo entre R$50.000 e R$100.000 e sinal verde quando for menor que R$50.000 | J17: H3643212 | K17: =_xlfn.XLOOKUP($J17,Tabela1[Código], Tabela1[Data de Validade],"Não",0) -> Não | L17: =_xlfn.XLOOKUP(J17,'Base de Dados'!B:B, 'Base de Dados'!C:C,"Não",0) -> Não | M17: =_xlfn.XLOOKUP($J17, 'Base de Dados'!B:B, 'Base de Dados'!A:A, "Não", 0) -> Não
J18: P577H891 | K18: =_xlfn.XLOOKUP($J18,Tabela1[Código], Tabela1[Data de Validade],"Não",0) -> 46650 | L18: =_xlfn.XLOOKUP(J18,'Base de Dados'!B:B, 'Base de Dados'!C:C,"Não",0) -> RJ | M18: =_xlfn.XLOOKUP($J18, 'Base de Dados'!B:B, 'Base de Dados'!A:A, "Não", 0) -> Vetoci
J19: H298P268 | K19: =_xlfn.XLOOKUP($J19,Tabela1[Código], Tabela1[Data de Validade],"Não",0) -> 46770 | L19: =_xlfn.XLOOKUP(J19,'Base de Dados'!B:B, 'Base de Dados'!C:C,"Não",0) -> GO | M19: =_xlfn.XLOOKUP($J19, 'Base de Dados'!B:B, 'Base de Dados'!A:A, "Não", 0) -> Vidipu
J20: P6545323 | K20: =_xlfn.XLOOKUP($J20,Tabela1[Código], Tabela1[Data de Validade],"Não",0) -> Não | L20: =_xlfn.XLOOKUP(J20,'Base de Dados'!B:B, 'Base de Dados'!C:C,"Não",0) -> Não | M20: =_xlfn.XLOOKUP($J20, 'Base de Dados'!B:B, 'Base de Dados'!A:A, "Não", 0) -> Não
C21: Pinte o preenchimento das células da coluna País de Destino. A cor da célula deve mudar automaticamente quando o País for alterado. Cada país terá uma cor específica conforme abaixo: | J21: H445H467 | K21: =_xlfn.XLOOKUP($J21,Tabela1[Código], Tabela1[Data de Validade],"Não",0) -> 45758 | L21: =_xlfn.XLOOKUP(J21,'Base de Dados'!B:B, 'Base de Dados'!C:C,"Não",0) -> AL | M21: =_xlfn.XLOOKUP($J21, 'Base de Dados'!B:B, 'Base de Dados'!A:A, "Não", 0) -> Rurofelupa
J22: H484H675 | K22: =_xlfn.XLOOKUP($J22,Tabela1[Código], Tabela1[Data de Validade],"Não",0) -> 46926 | L22: =_xlfn.XLOOKUP(J22,'Base de Dados'!B:B, 'Base de Dados'!C:C,"Não",0) -> GO | M22: =_xlfn.XLOOKUP($J22, 'Base de Dados'!B:B, 'Base de Dados'!A:A, "Não", 0) -> Favidufere
C24: Holanda | D24: Austrália | E24: Panamá | F24: Espanha | J24: Crie uma coluna na base de dados com as Regiões de Origem de cada produto de acordo com os Estados de Origem.
C26: Agora pinte a linha inteira de acordo com o País de Destino, não apenas as células da coluna País de Destino. A cor das células da linha deve mudar automaticamente quando o país for alterado.
J27: Estado | K27: Região
J28: AL | K28: Nordeste
J29: ES | K29: Sudeste
C30: Crie um filtro na base de dados e ordene a base de acordo com a data de validade (do mais antigo para o mais novo) | J30: GO | K30: Centro-Oeste
J31: MA | K31: Nordeste
J32: MG | K32: Sudeste
C33: Preencha as células abaixo com o o somatório, média, contagem, valor máximo e mínimo da coluna de custo de produção. Esses valores precisam ser recalculados automaticamente quando os valores da base forem alterados | J33: RJ | K33: Sudeste
J34: SP | K34: Sudeste
J36: Monte um quadro resumo com o custo total de produção levando em consideração a Região de Origem e o País de Destino.
C37: Somatório | D37: Média | E37: Contagem | F37: Máximo | G37: Mínimo
C38: =SUM('Base de Dados'!J:J) -> 272140218 | D38: =AVERAGE('Base de Dados'!J:J) -> 70594.09 | E38: =COUNT('Base de Dados'!J:J) -> 3855 | F38: =MAX('Base de Dados'!J:J) -> 119945 | G38: =MIN('Base de Dados'!J:J) -> 20044 | K38: Austrália | L38: Espanha | M38: Holanda | N38: Panamá
J39: Nordeste | K39: =SUMIFS('Base de Dados'!$J:$J, 'Base de Dados'!$K:$K, 'Perguntas 1 a 24'!K$38,'Base de Dados'!$D:$D, 'Perguntas 1 a 24'!$J39) -> 21582443 | L39: =SUMIFS('Base de Dados'!$J:$J, 'Base de Dados'!$K:$K, 'Perguntas 1 a 24'!L$38,'Base de Dados'!$D:$D, 'Perguntas 1 a 24'!$J39) -> 18432363 | M39: =SUMIFS('Base de Dados'!$J:$J, 'Base de Dados'!$K:$K, 'Perguntas 1 a 24'!M$38,'Base de Dados'!$D:$D, 'Perguntas 1 a 24'!$J39) -> 19384102 | N39: =SUMIFS('Base de Dados'!$J:$J, 'Base de Dados'!$K:$K, 'Perguntas 1 a 24'!N$38,'Base de Dados'!$D:$D, 'Perguntas 1 a 24'!$J39) -> 19329788
C40: Agora preencha o resumo abaixo com as mesmas informações do exercício anterior, mas de forma que os valores sejam atualizados quando os filtros aplicados na base de dados forem alterados. | J40: Sudeste | K40: =SUMIFS('Base de Dados'!$J:$J, 'Base de Dados'!$K:$K, 'Perguntas 1 a 24'!K$38,'Base de Dados'!$D:$D, 'Perguntas 1 a 24'!$J40) -> 37494439 | L40: =SUMIFS('Base de Dados'!$J:$J, 'Base de Dados'!$K:$K, 'Perguntas 1 a 24'!L$38,'Base de Dados'!$D:$D, 'Perguntas 1 a 24'!$J40) -> 38989407 | M40: =SUMIFS('Base de Dados'!$J:$J, 'Base de Dados'!$K:$K, 'Perguntas 1 a 24'!M$38,'Base de Dados'!$D:$D, 'Perguntas 1 a 24'!$J40) -> 38539749 | N40: =SUMIFS('Base de Dados'!$J:$J, 'Base de Dados'!$K:$K, 'Perguntas 1 a 24'!N$38,'Base de Dados'!$D:$D, 'Perguntas 1 a 24'!$J40) -> 37891952
J41: Centro-Oeste | K41: =SUMIFS('Base de Dados'!$J:$J, 'Base de Dados'!$K:$K, 'Perguntas 1 a 24'!K$38,'Base de Dados'!$D:$D, 'Perguntas 1 a 24'!$J41) -> 12025755 | L41: =SUMIFS('Base de Dados'!$J:$J, 'Base de Dados'!$K:$K, 'Perguntas 1 a 24'!L$38,'Base de Dados'!$D:$D, 'Perguntas 1 a 24'!$J41) -> 9401319 | M41: =SUMIFS('Base de Dados'!$J:$J, 'Base de Dados'!$K:$K, 'Perguntas 1 a 24'!M$38,'Base de Dados'!$D:$D, 'Perguntas 1 a 24'!$J41) -> 9133421 | N41: =SUMIFS('Base de Dados'!$J:$J, 'Base de Dados'!$K:$K, 'Perguntas 1 a 24'!N$38,'Base de Dados'!$D:$D, 'Perguntas 1 a 24'!$J41) -> 9935480
J42: Norte | K42: =SUMIFS('Base de Dados'!$J:$J, 'Base de Dados'!$K:$K, 'Perguntas 1 a 24'!K$38,'Base de Dados'!$D:$D, 'Perguntas 1 a 24'!$J42) -> 0 | L42: =SUMIFS('Base de Dados'!$J:$J, 'Base de Dados'!$K:$K, 'Perguntas 1 a 24'!L$38,'Base de Dados'!$D:$D, 'Perguntas 1 a 24'!$J42) -> 0 | M42: =SUMIFS('Base de Dados'!$J:$J, 'Base de Dados'!$K:$K, 'Perguntas 1 a 24'!M$38,'Base de Dados'!$D:$D, 'Perguntas 1 a 24'!$J42) -> 0 | N42: =SUMIFS('Base de Dados'!$J:$J, 'Base de Dados'!$K:$K, 'Perguntas 1 a 24'!N$38,'Base de Dados'!$D:$D, 'Perguntas 1 a 24'!$J42) -> 0
J43: Total | K43: =SUM(K39:K42) -> 71102637 | L43: =SUM(L39:L42) -> 66823089 | M43: =SUM(M39:M42) -> 67057272 | N43: =SUM(N39:N42) -> 67157220
C44: Somatório | D44: Média | E44: Contagem | F44: Máximo | G44: Mínimo | J44: Para qual país irão mais produtos em quantidade de produtos? E em valor?
C45: =SUBTOTAL(9, 'Base de Dados'!J:J) -> 272140218 | D45: =SUBTOTAL(1, 'Base de Dados'!J:J) -> 70594.09 | E45: =SUBTOTAL(2, 'Base de Dados'!J:J) -> 3855 | F45: =SUBTOTAL(4, 'Base de Dados'!J:J) -> 119945 | G45: =SUBTOTAL(5, 'Base de Dados'!J:J) -> 20044
J46: Quantidade | K46: {=INDEX('Base de Dados'!K:K, MATCH(_xlfn.XLOOKUP(LARGE('Base de Dados'!O:O,1),'Base de Dados'!O:O, 'Base de Dados'!N:N,,0),'Base de Dados'!B:B,0), 0)} -> Holanda
C47: Utilizando a mesma estrutura do exercício anterior, preencha a tabela abaixo considerando apenas as linhas com origem RJ. É necessária alguma alteração na fórmula? | J47: Valor | K47: =INDEX(K38:N38, 1, MATCH(LARGE(K43:N43, 1), K43:N43, 0)) -> Austrália
J49: Monte uma tabela com os TOP 5 produtos com maior Custo de Produção. Complemente com as demais informações pedidas.
C50: Somatório | D50: Média | E50: Contagem | F50: Máximo | G50: Mínimo
...

Sheet Controle Financeiro
C1: 43101 | H1: 43132 | M1: 43160 | R1: 43191 | W1: 43221 | AB1: 43252 | AG1: 43282 | AL1: 43313 | AQ1: 43344 | AV1: 43374 | BA1: 43405 | BF1: 43435 | BK1: 43466 | BP1: 43497 | BU1: 43525 | BZ1: 43556 | CE1: 43586 | CJ1: 43617 | CO1: 43647 | CT1: 43678 | CY1: 43709 | DD1: 43739 | DI1: 43770 | DN1: 43800 | DS1: 43831 | DX1: 43862 | EC1: 43891 | EH1: 43922 | EM1: 43952 | ER1: 43983 | EW1: 44013 | FB1: 44044 | FG1: 44075 | FL1: 44105 | FQ1: 44136 | FV1: 44166 | GA1: 44197 | GF1: 44228 | GK1: 44256 | GP1: 44287 | GU1: 44317 | GZ1: 44348 | HE1: 44378 | HJ1: 44409 | HO1: 44440 | HT1: 44470 | HY1: 44501 | ID1: 44531 | II1: 44562 | IN1: 44593 | IS1: 44621 | IX1: 44652 | JC1: 44682 | JH1: 44713 | JM1: 44743 | JR1: 44774 | JW1: 44805 | KB1: 44835 | KG1: 44866 | KL1: 44896 | KQ1: 44927 | KV1: 44958 | LA1: 44986 | LF1: 45017 | LK1: 45047 | LP1: 45078 | LU1: 45108 | LZ1: 45139 | ME1: 45170 | MJ1: 45200 | MO1: 45231 | MT1: 45261
B2: Descrição | C2: S1 | D2: S2 | E2: S3 | F2: S4 | G2: Crédito | H2: S1 | I2: S2 | J2: S3 | K2: S4 | L2: Crédito | M2: S1 | N2: S2 | O2: S3 | P2: S4 | Q2: Crédito | R2: S1 | S2: S2 | T2: S3 | U2: S4 | V2: Crédito | W2: S1 | X2: S2 | Y2: S3 | Z2: S4 | AA2: Crédito | AB2: S1 | AC2: S2 | AD2: S3 | AE2: S4 | AF2: Crédito | AG2: S1 | AH2: S2 | AI2: S3 | AJ2: S4 | AK2: Crédito | AL2: S1 | AM2: S2 | AN2: S3 | AO2: S4 | AP2: Crédito | AQ2: S1 | AR2: S2 | AS2: S3 | AT2: S4 | AU2: Crédito | AV2: S1 | AW2: S2 | AX2: S3 | AY2: S4 | AZ2: Crédito | BA2: S1 | BB2: S2 | BC2: S3 | BD2: S4 | BE2: Crédito | BF2: S1 | BG2: S2 | BH2: S3 | BI2: S4 | BJ2: Crédito | BK2: S1 | BL2: S2 | BM2: S3 | BN2: S4 | BO2: Crédito | BP2: S1 | BQ2: S2 | BR2: S3 | BS2: S4 | BT2: Crédito | BU2: S1 | BV2: S2 | BW2: S3 | BX2: S4 | BY2: Crédito | BZ2: S1 | CA2: S2 | CB2: S3 | CC2: S4 | CD2: Crédito | CE2: S1 | CF2: S2 | CG2: S3 | CH2: S4 | CI2: Crédito | CJ2: S1 | CK2: S2 | CL2: S3 | CM2: S4 | CN2: Crédito | CO2: S1 | CP2: S2 | CQ2: S3 | CR2: S4 | CS2: Crédito | CT2: S1 | CU2: S2 | CV2: S3 | CW2: S4 | CX2: Crédito | CY2: S1 | CZ2: S2 | DA2: S3 | DB2: S4 | DC2: Crédito | DD2: S1 | DE2: S2 | DF2: S3 | DG2: S4 | DH2: Crédito | DI2: S1 | DJ2: S2 | DK2: S3 | DL2: S4 | DM2: Crédito | DN2: S1 | DO2: S2 | DP2: S3 | DQ2: S4 | DR2: Crédito | DS2: S1 | DT2: S2 | DU2: S3 | DV2: S4 | DW2: Crédito | DX2: S1 | DY2: S2 | DZ2: S3 | EA2: S4 | EB2: Crédito | EC2: S1 | ED2: S2 | EE2: S3 | EF2: S4 | EG2: Crédito | EH2: S1 | EI2: S2 | EJ2: S3 | EK2: S4 | EL2: Crédito | EM2: S1 | EN2: S2 | EO2: S3 | EP2: S4 | EQ2: Crédito | ER2: S1 | ES2: S2 | ET2: S3 | EU2: S4 | EV2: Crédito | EW2: S1 | EX2: S2 | EY2: S3 | EZ2: S4 | FA2: Crédito | FB2: S1 | FC2: S2 | FD2: S3 | FE2: S4 | FF2: Crédito | FG2: S1 | FH2: S2 | FI2: S3 | FJ2: S4 | FK2: Crédito | FL2: S1 | FM2: S2 | FN2: S3 | FO2: S4 | FP2: Crédito | FQ2: S1 | FR2: S2 | FS2: S3 | FT2: S4 | FU2: Crédito | FV2: S1 | FW2: S2 | FX2: S3 | FY2: S4 | FZ2: Crédito | GA2: S1 | GB2: S2 | GC2: S3 | GD2: S4 | GE2: Crédito | GF2: S1 | GG2: S2 | GH2: S3 | GI2: S4 | GJ2: Crédito | GK2: S1 | GL2: S2 | GM2: S3 | GN2: S4 | GO2: Crédito | GP2: S1 | GQ2: S2 | GR2: S3 | GS2: S4 | GT2: Crédito | GU2: S1 | GV2: S2 | GW2: S3 | GX2: S4 | GY2: Crédito | GZ2: S1 | HA2: S2 | HB2: S3 | HC2: S4 | HD2: Crédito | HE2: S1 | HF2: S2 | HG2: S3 | HH2: S4 | HI2: Crédito | HJ2: S1 | HK2: S2 | HL2: S3 | HM2: S4 | HN2: Crédito | HO2: S1 | HP2: S2 | HQ2: S3 | HR2: S4 | HS2: Crédito | HT2: S1 | HU2: S2 | HV2: S3 | HW2: S4 | HX2: Crédito | HY2: S1 | HZ2: S2 | IA2: S3 | IB2: S4 | IC2: Crédito | ID2: S1 | IE2: S2 | IF2: S3 | IG2: S4 | IH2: Crédito | II2: S1 | IJ2: S2 | IK2: S3 | IL2: S4 | IM2: Crédito | IN2: S1 | IO2: S2 | IP2: S3 | IQ2: S4 | IR2: Crédito | IS2: S1 | IT2: S2 | IU2: S3 | IV2: S4 | IW2: Crédito | IX2: S1 | IY2: S2 | IZ2: S3 | JA2: S4 | JB2: Crédito | JC2: S1 | JD2: S2 | JE2: S3 | JF2: S4 | JG2: Crédito | JH2: S1 | JI2: S2 | JJ2: S3 | JK2: S4 | JL2: Crédito | JM2: S1 | JN2: S2 | JO2: S3 | JP2: S4 | JQ2: Crédito | JR2: S1 | JS2: S2 | JT2: S3 | JU2: S4 | JV2: Crédito | JW2: S1 | JX2: S2 | JY2: S3 | JZ2: S4 | KA2: Crédito | KB2: S1 | KC2: S2 | KD2: S3 | KE2: S4 | KF2: Crédito | KG2: S1 | KH2: S2 | KI2: S3 | KJ2: S4 | KK2: Crédito | KL2: S1 | KM2: S2 | KN2: S3 | KO2: S4 | KP2: Crédito | KQ2: S1 | KR2: S2 | KS2: S3 | KT2: S4 | KU2: Crédito | KV2: S1 | KW2: S2 | KX2: S3 | KY2: S4 | KZ2: Crédito | LA2: S1 | LB2: S2 | LC2: S3 | LD2: S4 | LE2: Crédito | LF2: S1 | LG2: S2 | LH2: S3 | LI2: S4 | LJ2: Crédito | LK2: S1 | LL2: S2 | LM2: S3 | LN2: S4 | LO2: Crédito | LP2: S1 | LQ2: S2 | LR2: S3 | LS2: S4 | LT2: Crédito | LU2: S1 | LV2: S2 | LW2: S3 | LX2: S4 | LY2: Crédito | LZ2: S1 | MA2: S2 | MB2: S3 | MC2: S4 | MD2: Crédito | ME2: S1 | MF2: S2 | MG2: S3 | MH2: S4 | MI2: Crédito | MJ2: S1 | MK2: S2 | ML2: S3 | MM2: S4 | MN2: Crédito | MO2: S1 | MP2: S2 | MQ2: S3 | MR2: S4 | MS2: Crédito | MT2: S1 | MU2: S2 | MV2: S3 | MW2: S4 | MX2: Crédito
